<?xml version='1.0'?>

<robot name="Rover" xmlns:xacro="http://www.ros.org/wiki/xacro">

  <xacro:include filename="$(find rover_description)/urdf/rover.gazebo" />
  <xacro:include filename="$(find rover_description)/urdf/materials.xacro"/>
  <xacro:include filename="$(find rover_description)/urdf/lidar.xacro"/>

  <link name='base_footprint'>
    <pose>0 0 0 0 0 0</pose>

    <inertial>
      <mass value="15.0"/>
      <origin xyz="0.0 0 0.1" rpy=" 0 0 0"/>
      <inertia
          ixx="0.1"
          ixy="0"
          ixz="0"
          iyy="0.1"
          iyz="0"
          izz="0.1"/>
    </inertial>

    <collision name='collision'>
      <origin xyz="0 0 0.15" rpy=" 0 0 0"/>
      <geometry>
        <box size= "1 0.5 0.35"/>
      </geometry>
    </collision>

    <visual name='base_footprint_visual'>
      <origin xyz="0 0 0.15" rpy=" 0 0 0"/>
      <geometry>

        <box size= "1 0.5 0.35"/>
      </geometry>
    </visual>
  </link>

  <link name="left_wheel_front">
    <collision name="collision">
      <origin xyz="0 0 0" rpy="0 1.5707 1.5707"/>
      <geometry>
        <cylinder radius="0.13" length="0.04"/>
      </geometry>
    </collision>

    <visual name="left_wheel_visual">
      <origin xyz="0 0 0" rpy="0 1.5707 1.5707"/>
      <geometry>
        <cylinder radius="0.13" length="0.04"/>
      </geometry>
    </visual>

    <inertial>
      <origin xyz="0 0 0" rpy="0 1.5707 1.5707"/>
      <mass value="5"/>
      <inertia
        ixx=".1" ixy="0.0" ixz="0.0"
        iyy=".1" iyz="0.0"
        izz=".1"/>
    </inertial>
  </link>

  <link name="right_wheel_front">
    <collision name="collision">
      <origin xyz="0 0 0" rpy="0 1.5707 1.5707"/>
      <geometry>
        <cylinder radius="0.13" length="0.04"/>
      </geometry>
    </collision>

    <visual name="right_wheel_visual">
      <origin xyz="0 0 0" rpy="0 1.5707 1.5707"/>
      <geometry>
        <cylinder radius="0.13" length="0.04"/>
      </geometry>
    </visual>

    <inertial>
      <origin xyz="0 0 0" rpy="0 1.5707 1.5707"/>
      <mass value="5"/>
      <inertia
        ixx=".1" ixy="0.0" ixz="0.0"
        iyy=".1" iyz="0.0"
        izz=".1"/>
    </inertial>
  </link>

  <link name="left_wheel_back">
    <collision name="collision">
      <origin xyz="0 0 0" rpy="0 1.5707 1.5707"/>
      <geometry>
        <cylinder radius="0.13" length="0.04"/>
      </geometry>
    </collision>

    <visual name="left_wheel_visual">
      <origin xyz="0 0 0" rpy="0 1.5707 1.5707"/>
      <geometry>
        <cylinder radius="0.13" length="0.04"/>
      </geometry>
    </visual>

    <inertial>
      <origin xyz="0 0 0" rpy="0 1.5707 1.5707"/>
      <mass value="5"/>
      <inertia
        ixx=".1" ixy="0.0" ixz="0.0"
        iyy=".1" iyz="0.0"
        izz=".1"/>
    </inertial>
  </link>

  <link name="right_wheel_back">
    <collision name="collision">
      <origin xyz="0 0 0" rpy="0 1.5707 1.5707"/>
      <geometry>
        <cylinder radius="0.13" length="0.04"/>
      </geometry>
    </collision>

    <visual name="right_wheel_visual">
      <origin xyz="0 0 0" rpy="0 1.5707 1.5707"/>
      <geometry>
        <cylinder radius="0.13" length="0.04"/>
      </geometry>
    </visual>

    <inertial>
      <origin xyz="0 0 0" rpy="0 1.5707 1.5707"/>
      <mass value="5"/>
      <inertia
        ixx=".1" ixy="0.0" ixz="0.0"
        iyy=".1" iyz="0.0"
        izz=".1"/>
    </inertial>
  </link>


  <joint type="continuous" name="left_wheel_front_hinge">
    <origin xyz="0.25 0.29 0" rpy="0 0 0"/>
    <child link="left_wheel_front"/>
    <parent link="base_footprint"/>
    <axis xyz="0 1 0" rpy="0 0 0"/>
    <limit effort="10000" velocity="1000"/>
    <joint_properties damping="1.0" friction="1.0"/>
  </joint>

  <joint type="continuous" name="right_wheel_front_hinge">
    <origin xyz="0.25 -0.29 0" rpy="0 0 0"/>
    <child link="right_wheel_front"/>
    <parent link="base_footprint"/>
    <axis xyz="0 1 0" rpy="0 0 0"/>
    <limit effort="10000" velocity="1000"/>
    <joint_properties damping="1.0" friction="1.0"/>
  </joint>

  <joint type="continuous" name="left_wheel_back_hinge">
    <origin xyz="-0.25 0.29 0" rpy="0 0 0"/>
    <child link="left_wheel_back"/>
    <parent link="base_footprint"/>
    <axis xyz="0 1 0" rpy="0 0 0"/>
    <limit effort="10000" velocity="1000"/>
    <joint_properties damping="1.0" friction="1.0"/>
  </joint>

  <joint type="continuous" name="right_wheel_back_hinge">
    <origin xyz="-0.25 -0.29 0" rpy="0 0 0"/>
    <child link="right_wheel_back"/>
    <parent link="base_footprint"/>
    <axis xyz="0 1 0" rpy="0 0 0"/>
    <limit effort="10000" velocity="1000"/>
    <joint_properties damping="1.0" friction="1.0"/>
  </joint>

  <joint name="ir_front_joint" type="fixed">
    <axis xyz="0 1 0" />
    <origin rpy="0 0 0" xyz="0.5 0 0" />
    <parent link="base_footprint"/>
    <child link="base_ir_front"/>
  </joint>
  <link name="base_ir_front">
      <collision>
        <origin xyz="0 0 0" rpy="0 0 0"/>
        <geometry>
          <box size="0.01 0.01 0.01"/>
        </geometry>
      </collision>
      <visual>
        <origin xyz="0 0 0" rpy="0 0 0"/>
        <geometry>
          <box size="0.01 0.01 0.01"/>
        </geometry>
      </visual>
      <inertial>
        <mass value="1e-5" />
        <origin xyz="0 0 0" rpy="0 0 0"/>
        <inertia ixx="1e-6" ixy="0" ixz="0" iyy="1e-6" iyz="0" izz="1e-6" />
      </inertial>
  </link>

  <joint name="ir_frontR_joint" type="fixed">
    <axis xyz="0 1 0" />
    <origin rpy="0 0 0.7854" xyz="0.5 0.25 0" />
    <parent link="base_footprint"/>
    <child link="base_ir_frontR"/>
  </joint>
  <link name="base_ir_frontR">
      <collision>
        <origin xyz="0 0 0" rpy="0 0 0"/>
        <geometry>
          <box size="0.01 0.01 0.01"/>
        </geometry>
      </collision>
      <visual>
        <origin xyz="0 0 0" rpy="0 0 0"/>
        <geometry>
          <box size="0.01 0.01 0.01"/>
        </geometry>
      </visual>
      <inertial>
        <mass value="1e-5" />
        <origin xyz="0 0 0" rpy="0 0 0"/>
        <inertia ixx="1e-6" ixy="0" ixz="0" iyy="1e-6" iyz="0" izz="1e-6" />
      </inertial>
  </link>

  <joint name="ir_frontL_joint" type="fixed">
    <axis xyz="0 1 0" />
    <origin rpy="0 0 -0.7854" xyz="0.5 -0.25 0" />
    <parent link="base_footprint"/>
    <child link="base_ir_frontL"/>
  </joint>
  <link name="base_ir_frontL">
      <collision>
        <origin xyz="0 0 0" rpy="0 0 0"/>
        <geometry>
          <box size="0.01 0.01 0.01"/>
        </geometry>
      </collision>
      <visual>
        <origin xyz="0 0 0" rpy="0 0 0"/>
        <geometry>
          <box size="0.01 0.01 0.01"/>
        </geometry>
      </visual>
      <inertial>
        <mass value="1e-5" />
        <origin xyz="0 0 0" rpy="0 0 0"/>
        <inertia ixx="1e-6" ixy="0" ixz="0" iyy="1e-6" iyz="0" izz="1e-6" />
      </inertial>
  </link>

  <joint name="ir_rear_joint" type="fixed">
    <axis xyz="0 1 0" />
    <origin rpy="0 0 2.7925" xyz="-0.5 0 0" />
    <parent link="base_footprint"/>
    <child link="base_ir_rear"/>
  </joint>
  <link name="base_ir_rear">
      <collision>
        <origin xyz="0 0 0" rpy="0 0 0"/>
        <geometry>
          <box size="0.01 0.01 0.01"/>
        </geometry>
      </collision>
      <visual>
        <origin xyz="0 0 0" rpy="0 0 0"/>
        <geometry>
          <box size="0.01 0.01 0.01"/>
        </geometry>
      </visual>
      <inertial>
        <mass value="1e-5" />
        <origin xyz="0 0 0" rpy="0 0 0"/>
        <inertia ixx="1e-6" ixy="0" ixz="0" iyy="1e-6" iyz="0" izz="1e-6" />
      </inertial>
  </link>

  <joint name="ir_rearR_joint" type="fixed">
    <axis xyz="0 1 0" />
    <origin rpy="0 0 2.3562" xyz="-0.5 0.25 0" />
    <parent link="base_footprint"/>
    <child link="base_ir_rearR"/>
  </joint>
  <link name="base_ir_rearR">
      <collision>
        <origin xyz="0 0 0" rpy="0 0 0"/>
        <geometry>
          <box size="0.01 0.01 0.01"/>
        </geometry>
      </collision>
      <visual>
        <origin xyz="0 0 0" rpy="0 0 0"/>
        <geometry>
          <box size="0.01 0.01 0.01"/>
        </geometry>
      </visual>
      <inertial>
        <mass value="1e-5" />
        <origin xyz="0 0 0" rpy="0 0 0"/>
        <inertia ixx="1e-6" ixy="0" ixz="0" iyy="1e-6" iyz="0" izz="1e-6" />
      </inertial>
  </link>

  <joint name="ir_rearL_joint" type="fixed">
    <axis xyz="0 1 0" />
    <origin rpy="0 0 -2.3562" xyz="-0.5 -0.25 0" />
    <parent link="base_footprint"/>
    <child link="base_ir_rearL"/>
  </joint>
  <link name="base_ir_rearL">
      <collision>
        <origin xyz="0 0 0" rpy="0 0 0"/>
        <geometry>
          <box size="0.01 0.01 0.01"/>
        </geometry>
      </collision>
      <visual>
        <origin xyz="0 0 0" rpy="0 0 0"/>
        <geometry>
          <box size="0.01 0.01 0.01"/>
        </geometry>
      </visual>
      <inertial>
        <mass value="1e-5" />
        <origin xyz="0 0 0" rpy="0 0 0"/>
        <inertia ixx="1e-6" ixy="0" ixz="0" iyy="1e-6" iyz="0" izz="1e-6" />
      </inertial>
  </link>

  <joint name="ir_sideL_joint" type="fixed">
    <axis xyz="0 1 0" />
    <origin rpy="0 0 -1.5708" xyz="0 0.25 0" />
    <parent link="base_footprint"/>
    <child link="base_ir_sideL"/>
  </joint>
  <link name="base_ir_sideL">
      <collision>
        <origin xyz="0 0 0" rpy="0 0 0"/>
        <geometry>
          <box size="0.01 0.01 0.01"/>
        </geometry>
      </collision>
      <visual>
        <origin xyz="0 0 0" rpy="0 0 0"/>
        <geometry>
          <box size="0.01 0.01 0.01"/>
        </geometry>
      </visual>
      <inertial>
        <mass value="1e-5" />
        <origin xyz="0 0 0" rpy="0 0 0"/>
        <inertia ixx="1e-6" ixy="0" ixz="0" iyy="1e-6" iyz="0" izz="1e-6" />
      </inertial>
  </link>

  <joint name="ir_sideR_joint" type="fixed">
    <axis xyz="0 1 0" />
    <origin rpy="0 0 1.5708" xyz="0 -0.25 0" />
    <parent link="base_footprint"/>
    <child link="base_ir_sideR"/>
  </joint>
  <link name="base_ir_sideR">
      <collision>
        <origin xyz="0 0 0" rpy="0 0 0"/>
        <geometry>
          <box size="0.01 0.01 0.01"/>
        </geometry>
      </collision>
      <visual>
        <origin xyz="0 0 0" rpy="0 0 0"/>
        <geometry>
          <box size="0.01 0.01 0.01"/>
        </geometry>
      </visual>
      <inertial>
        <mass value="1e-5" />
        <origin xyz="0 0 0" rpy="0 0 0"/>
        <inertia ixx="1e-6" ixy="0" ixz="0" iyy="1e-6" iyz="0" izz="1e-6" />
      </inertial>
  </link>

</robot>
